Workbook
Name d8d59fd6: area!$A$12
Name i1f244f1: area!$A$93
Name j153b7e5: area!$A$69
Name rf7639e5: area!$A$32
Name v4bdaae4: area!$A$84
Name xf5ffb76: area!$A$57
Name yfd8a144: area!$A$110

Sheet char
A1: id | B1: name | C1: height | D1: type | E1: school
A2: 0 | B2: 童子切安綱 剥落 | C2: 178 | D2: 太刀
A3: 3 | B3: 三日月宗近 | C3: 180 | D3: 太刀 | E3: 三条
A4: 5 | B4: 小狐丸 | C4: 188 | D4: 太刀 | E4: 三条
A5: 7 | B5: 石切丸 | C5: 189 | D5: 大太刀 | E5: 三条
A6: 9 | B6: 岩融 | C6: 203 | D6: 薙刀 | E6: 三条
A7: 11 | B7: 今剣 | C7: 123 | D7: 短刀 | E7: 三条
A8: 13 | B8: 大典太光世 | C8: 190 | D8: 太刀 | E8: 三池
A9: 15 | B9: ソハヤノツルキ | C9: 178 | D9: 太刀 | E9: 三池
A10: 17 | B10: 数珠丸恒次 | C10: 181 | D10: 太刀 | E10: 青江
A11: 19 | B11: にっかり青江 | C11: 167 | D11: 脇差 | E11: 青江
A12: 21 | B12: 鬼丸国綱 | C12: 193 | D12: 太刀 | E12: 粟田口
A13: 23 | B13: 鳴狐 | C13: 164 | D13: 打刀 | E13: 粟田口
A14: 25 | B14: 一期一振 | C14: 177 | D14: 太刀 | E14: 粟田口
... A43: 83 | B43: 小夜左文字 | C43: 118 | D43: 短刀 | E43: 左文字
A44: 85 | B44: 加州清光 | C44: 165 | D44: 打刀
A45: 87 | B45: 大和守安定 | C45: 165 | D45: 打刀
A46: 89 | B46: 歌仙兼定 | C46: 175 | D46: 打刀 | E46: 兼定
A47: 91 | B47: 和泉守兼定 | C47: 186 | D47: 打刀 | E47: 兼定
A48: 93 | B48: 陸奥守吉行 | C48: 174 | D48: 打刀
A49: 95 | B49: 山姥切国広 | C49: 172 | D49: 打刀 | E49: 国広
A50: 97 | B50: 山伏国広 | C50: 188 | D50: 太刀 | E50: 国広
A51: 99 | B51: 堀川国広 | C51: 160 | D51: 脇差 | E51: 国広
A52: 101 | B52: 蜂須賀虎徹 | C52: 176 | D52: 打刀 | E52: 虎徹
A53: 103 | B53: 浦島虎徹 | C53: 157 | D53: 脇差 | E53: 虎徹
A54: 105 | B54: 長曽祢虎徹 | C54: 187 | D54: 打刀 | E54: 虎徹…？
A55: 107 | B55: 髭切 | C55: 178 | D55: 太刀
A56: 112 | B56: 膝丸 | C56: 179 | D56: 太刀
A57: 116 | B57: 大倶利伽羅 | C57: 175 | D57: 打刀 | E57: 広光
A58: 118 | B58: へし切長谷部 | C58: 178 | D58: 打刀
A59: 120 | B59: 不動行光 | C59: 154 | D59: 短刀
A60: 122 | B60: 獅子王 | C60: 166 | D60: 太刀
A61: 124 | B61: 小烏丸 | C61: 155 | D61: 太刀
A62: 126 | B62: 抜丸 | C62: 157 | D62: 太刀
A63: 128 | B63: 同田貫正国 | C63: 169 | D63: 打刀
A64: 130 | B64: 鶴丸国永 | C64: 177 | D64: 太刀
A65: 132 | B65: 太郎太刀 | C65: 196 | D65: 大太刀
A66: 134 | B66: 次郎太刀 | C66: 190 | D66: 大太刀
A67: 136 | B67: 日本号 | C67: 195 | D67: 槍
A68: 138 | B68: 御手杵 | C68: 192 | D68: 槍
...

Sheet status_a
A1: id | B1: seizon | C1: dageki | D1: tosotsu | E1: kido | F1: syoryoku | G1: teisatsu | H1: inpei | I1: hissatsu
A2: 0 | B2: 55 | C2: 74 | D2: 70 | E2: 50 | F2: 50 | G2: 33 | H2: 34 | I2: 44
A3: 3 | B3: 63 | C3: 72 | D3: 72 | E3: 37 | F3: 55 | G3: 38 | H3: 35 | I3: 30
A4: 5 | B4: 58 | C4: 68 | D4: 69 | E4: 41 | F4: 53 | G4: 38 | H4: 30 | I4: 28
A5: 7 | B5: 72 | C5: 85 | D5: 68 | E5: 13 | F5: 61 | G5: 15 | H5: 23 | I5: 32
A6: 9 | B6: 60 | C6: 68 | D6: 51 | E6: 42 | F6: 61 | G6: 41 | H6: 35 | I6: 29
A7: 11 | B7: 33 | C7: 26 | D7: 38 | E7: 58 | F7: 31 | G7: 49 | H7: 40 | I7: 45
A8: 13 | B8: 70 | C8: 76 | D8: 70 | E8: 35 | F8: 52 | G8: 30 | H8: 27 | I8: 37
A9: 15 | B9: 61 | C9: 70 | D9: 72 | E9: 48 | F9: 49 | G9: 32 | H9: 31 | I9: 25
A10: 17 | B10: 71 | C10: 62 | D10: 78 | E10: 38 | F10: 52 | G10: 34 | H10: 30 | I10: 29
A11: 19 | B11: 39 | C11: 44 | D11: 46 | E11: 52 | F11: 41 | G11: 55 | H11: 45 | I11: 40
A12: 21 | B12: 64 | C12: 77 | D12: 67 | E12: 44 | F12: 54 | G12: 33 | H12: 30 | I12: 33
A13: 23 | B13: 48 | C13: 58 | D13: 50 | E13: 51 | F13: 53 | G13: 46 | H13: 41 | I13: 35
... A128: 258 | B128: 63 | C128: 73 | D128: 62 | E128: 49 | F128: 51 | G128: 31 | H128: 28 | I128: 36
A129: 260 | C129: 63 | D129: 76 | E129: 39 | F129: 47 | H129: 35 | I129: 28
A130: 262

Sheet status_b
A1: id | B1: seizon | C1: dageki | D1: tosotsu | E1: kido | F1: syoryoku | G1: teisatsu | H1: inpei | I1: hissatsu
A2: 4 | B2: 101 | C2: 129 | D2: 130 | E2: 67 | F2: 89 | G2: 66 | H2: 69 | I2: 69
A3: 6 | B3: 102 | C3: 125 | D3: 120 | E3: 69 | F3: 86 | G3: 70 | H3: 56 | I3: 72
A4: 8 | B4: 105 | C4: 145 | D4: 112 | E4: 26 | F4: 93 | G4: 46 | H4: 50 | I4: 72
A5: 10 | B5: 77 | C5: 125 | D5: 98 | E5: 57 | F5: 115 | G5: 58 | H5: 58 | I5: 90
A6: 12 | B6: 50 | C6: 80 | D6: 82 | E6: 142 | F6: 35 | G6: 120 | H6: 109 | I6: 60
A7: 14 | B7: 105 | C7: 138 | D7: 131 | E7: 61 | F7: 87 | G7: 57 | H7: 59 | I7: 84
A8: 16 | B8: 96 | C8: 127 | D8: 129 | E8: 68 | F8: 84 | G8: 58 | H8: 64 | I8: 70
A9: 18 | B9: 106 | C9: 123 | D9: 144 | E9: 60 | F9: 81 | G9: 69 | H9: 63 | I9: 70
A10: 20 | B10: 68 | C10: 92 | D10: 88 | E10: 76 | F10: 48 | G10: 119 | H10: 143 | I10: 55
A11: 22 | B11: 103 | C11: 140 | D11: 120 | E11: 70 | F11: 89 | G11: 64 | H11: 61 | I11: 76
A12: 24 | B12: 67 | C12: 103 | D12: 98 | E12: 66 | F12: 69 | G12: 90 | H12: 82 | I12: 77
A13: 26 | B13: 94 | C13: 129 | D13: 128 | E13: 57 | F13: 97 | G13: 68 | H13: 65 | I13: 68
... A86: 179 | B86: 68 | C86: 110 | D86: 98 | E86: 64 | F86: 66 | G86: 85 | H86: 79 | I86: 89
A87: 181 | B87: 95 | C87: 132 | D87: 145 | E87: 59 | F87: 81 | H87: 58 | I87: 78
A88: 187 | C88: 101 | D88: 86 | E88: 78 | F88: 55 | H88: 142 | I88: 66

Sheet story
A1: id | B1: name | C1: area | D1: biko | E1: charA | F1: charB | G1: charC | H1: charD | I1: charE | J1: charF
A2: 1 | B2: 土方の話 | C2: 1-1 | E2: =IFERROR(INDEX(char!$A:$A, MATCH(N2, char!$B:$B, 0)), "") -> 91 | F2: =IFERROR(INDEX(char!$A:$A, MATCH(O2, char!$B:$B, 0)), "") -> 99 | G2: =IFERROR(INDEX(char!$A:$A, MATCH(P2, char!$B:$B, 0)), "") | H2: =IFERROR(INDEX(char!$A:$A, MATCH(Q2, char!$B:$B, 0)), "") | I2: =IFERROR(INDEX(char!$A:$A, MATCH(R2, char!$B:$B, 0)), "") | J2: =IFERROR(INDEX(char!$A:$A, MATCH(S2, char!$B:$B, 0)), "") | N2: 和泉守兼定 | O2: 堀川国広
A3: 2 | B3: 沖田の話 | C3: 1-4 | E3: =IFERROR(INDEX(char!$A:$A, MATCH(N3, char!$B:$B, 0)), "") -> 85 | F3: =IFERROR(INDEX(char!$A:$A, MATCH(O3, char!$B:$B, 0)), "") -> 87 | G3: =IFERROR(INDEX(char!$A:$A, MATCH(P3, char!$B:$B, 0)), "") | H3: =IFERROR(INDEX(char!$A:$A, MATCH(Q3, char!$B:$B, 0)), "") | I3: =IFERROR(INDEX(char!$A:$A, MATCH(R3, char!$B:$B, 0)), "") | J3: =IFERROR(INDEX(char!$A:$A, MATCH(S3, char!$B:$B, 0)), "") | N3: 加州清光 | O3: 大和守安定
A4: 3 | B4: 太朗と次郎 | C4: 2-1 | E4: =IFERROR(INDEX(char!$A:$A, MATCH(N4, char!$B:$B, 0)), "") -> 132 | F4: =IFERROR(INDEX(char!$A:$A, MATCH(O4, char!$B:$B, 0)), "") -> 134 | G4: =IFERROR(INDEX(char!$A:$A, MATCH(P4, char!$B:$B, 0)), "") | H4: =IFERROR(INDEX(char!$A:$A, MATCH(Q4, char!$B:$B, 0)), "") | I4: =IFERROR(INDEX(char!$A:$A, MATCH(R4, char!$B:$B, 0)), "") | J4: =IFERROR(INDEX(char!$A:$A, MATCH(S4, char!$B:$B, 0)), "") | N4: 太郎太刀 | O4: 次郎太刀
A5: 4 | B5: 無用の長物 | C5: 2-2 | E5: =IFERROR(INDEX(char!$A:$A, MATCH(N5, char!$B:$B, 0)), "") -> 128 | F5: =IFERROR(INDEX(char!$A:$A, MATCH(O5, char!$B:$B, 0)), "") -> 138 | G5: =IFERROR(INDEX(char!$A:$A, MATCH(P5, char!$B:$B, 0)), "") | H5: =IFERROR(INDEX(char!$A:$A, MATCH(Q5, char!$B:$B, 0)), "") | I5: =IFERROR(INDEX(char!$A:$A, MATCH(R5, char!$B:$B, 0)), "") | J5: =IFERROR(INDEX(char!$A:$A, MATCH(S5, char!$B:$B, 0)), "") | N5: 同田貫正国 | O5: 御手杵
A6: 5 | B6: 悲しみの剣たち | C6: 2-4 | E6: =IFERROR(INDEX(char!$A:$A, MATCH(N6, char!$B:$B, 0)), "") -> 25 | F6: =IFERROR(INDEX(char!$A:$A, MATCH(O6, char!$B:$B, 0)), "") -> 27 | G6: =IFERROR(INDEX(char!$A:$A, MATCH(P6, char!$B:$B, 0)), "") | H6: =IFERROR(INDEX(char!$A:$A, MATCH(Q6, char!$B:$B, 0)), "") | I6: =IFERROR(INDEX(char!$A:$A, MATCH(R6, char!$B:$B, 0)), "") | J6: =IFERROR(INDEX(char!$A:$A, MATCH(S6, char!$B:$B, 0)), "") | N6: 一期一振 | O6: 鯰尾藤四郎
A7: 6 | B7: 安土の名工 | C7: 3-4 | E7: =IFERROR(INDEX(char!$A:$A, MATCH(N7, char!$B:$B, 0)), "") -> 95 | F7: =IFERROR(INDEX(char!$A:$A, MATCH(O7, char!$B:$B, 0)), "") -> 97 | G7: =IFERROR(INDEX(char!$A:$A, MATCH(P7, char!$B:$B, 0)), "") | H7: =IFERROR(INDEX(char!$A:$A, MATCH(Q7, char!$B:$B, 0)), "") | I7: =IFERROR(INDEX(char!$A:$A, MATCH(R7, char!$B:$B, 0)), "") | J7: =IFERROR(INDEX(char!$A:$A, MATCH(S7, char!$B:$B, 0)), "") | N7: 山姥切国広 | O7: 山伏国広
A8: 7 | B8: 今川の剣 | C8: 4-3 | E8: =IFERROR(INDEX(char!$A:$A, MATCH(N8, char!$B:$B, 0)), "") -> 79 | F8: =IFERROR(INDEX(char!$A:$A, MATCH(O8, char!$B:$B, 0)), "") -> 81 | G8: =IFERROR(INDEX(char!$A:$A, MATCH(P8, char!$B:$B, 0)), "") | H8: =IFERROR(INDEX(char!$A:$A, MATCH(Q8, char!$B:$B, 0)), "") | I8: =IFERROR(INDEX(char!$A:$A, MATCH(R8, char!$B:$B, 0)), "") | J8: =IFERROR(INDEX(char!$A:$A, MATCH(S8, char!$B:$B, 0)), "") | N8: 江雪左文字 | O8: 宗三左文字
A9: 8 | B9: 義経の話 | C9: 5-4 | E9: =IFERROR(INDEX(char!$A:$A, MATCH(N9, char!$B:$B, 0)), "") -> 9 | F9: =IFERROR(INDEX(char!$A:$A, MATCH(O9, char!$B:$B, 0)), "") -> 11 | G9: =IFERROR(INDEX(char!$A:$A, MATCH(P9, char!$B:$B, 0)), "") | H9: =IFERROR(INDEX(char!$A:$A, MATCH(Q9, char!$B:$B, 0)), "") | I9: =IFERROR(INDEX(char!$A:$A, MATCH(R9, char!$B:$B, 0)), "") | J9: =IFERROR(INDEX(char!$A:$A, MATCH(S9, char!$B:$B, 0)), "") | N9: 岩融 | O9: 今剣
A10: 9 | B10: 神剣までの道 | E10: =IFERROR(INDEX(char!$A:$A, MATCH(N10, char!$B:$B, 0)), "") -> 7 | F10: =IFERROR(INDEX(char!$A:$A, MATCH(O10, char!$B:$B, 0)), "") -> 19 | G10: =IFERROR(INDEX(char!$A:$A, MATCH(P10, char!$B:$B, 0)), "") | H10: =IFERROR(INDEX(char!$A:$A, MATCH(Q10, char!$B:$B, 0)), "") | I10: =IFERROR(INDEX(char!$A:$A, MATCH(R10, char!$B:$B, 0)), "") | J10: =IFERROR(INDEX(char!$A:$A, MATCH(S10, char!$B:$B, 0)), "") | N10: 石切丸 | O10: にっかり青江
A11: 10 | B11: 藤四郎だらけなのは | E11: =IFERROR(INDEX(char!$A:$A, MATCH(N11, char!$B:$B, 0)), "") -> 33 | F11: =IFERROR(INDEX(char!$A:$A, MATCH(O11, char!$B:$B, 0)), "") -> 47 | G11: =IFERROR(INDEX(char!$A:$A, MATCH(P11, char!$B:$B, 0)), "") | H11: =IFERROR(INDEX(char!$A:$A, MATCH(Q11, char!$B:$B, 0)), "") | I11: =IFERROR(INDEX(char!$A:$A, MATCH(R11, char!$B:$B, 0)), "") | J11: =IFERROR(INDEX(char!$A:$A, MATCH(S11, char!$B:$B, 0)), "") | N11: 厚藤四郎 | O11: 五虎退
A12: 11 | B12: 来派の話 | E12: =IFERROR(INDEX(char!$A:$A, MATCH(N12, char!$B:$B, 0)), "") -> 59 | F12: =IFERROR(INDEX(char!$A:$A, MATCH(O12, char!$B:$B, 0)), "") -> 61 | G12: =IFERROR(INDEX(char!$A:$A, MATCH(P12, char!$B:$B, 0)), "") | H12: =IFERROR(INDEX(char!$A:$A, MATCH(Q12, char!$B:$B, 0)), "") | I12: =IFERROR(INDEX(char!$A:$A, MATCH(R12, char!$B:$B, 0)), "") | J12: =IFERROR(INDEX(char!$A:$A, MATCH(S12, char!$B:$B, 0)), "") | N12: 蛍丸 | O12: 愛染国俊
A13: 12 | B13: 足利家の話 | E13: =IFERROR(INDEX(char!$A:$A, MATCH(N13, char!$B:$B, 0)), "") -> 3 | F13: =IFERROR(INDEX(char!$A:$A, MATCH(O13, char!$B:$B, 0)), "") -> 29 | G13: =IFERROR(INDEX(char!$A:$A, MATCH(P13, char!$B:$B, 0)), "") | H13: =IFERROR(INDEX(char!$A:$A, MATCH(Q13, char!$B:$B, 0)), "") | I13: =IFERROR(INDEX(char!$A:$A, MATCH(R13, char!$B:$B, 0)), "") | J13: =IFERROR(INDEX(char!$A:$A, MATCH(S13, char!$B:$B, 0)), "") | N13: 三日月宗近 | O13: 骨喰藤四郎
A14: 13 | B14: 狐の話 | E14: =IFERROR(INDEX(char!$A:$A, MATCH(N14, char!$B:$B, 0)), "") -> 5 | F14: =IFERROR(INDEX(char!$A:$A, MATCH(O14, char!$B:$B, 0)), "") -> 23 | G14: =IFERROR(INDEX(char!$A:$A, MATCH(P14, char!$B:$B, 0)), "") | H14: =IFERROR(INDEX(char!$A:$A, MATCH(Q14, char!$B:$B, 0)), "") | I14: =IFERROR(INDEX(char!$A:$A, MATCH(R14, char!$B:$B, 0)), "") | J14: =IFERROR(INDEX(char!$A:$A, MATCH(S14, char!$B:$B, 0)), "") | N14: 小狐丸 | O14: 鳴狐
A15: 14 | B15: 近藤VS龍馬 | C15: 1-4 | E15: =IFERROR(INDEX(char!$A:$A, MATCH(N15, char!$B:$B, 0)), "") -> 93 | F15: =IFERROR(INDEX(char!$A:$A, MATCH(O15, char!$B:$B, 0)), "") -> 105 | G15: =IFERROR(INDEX(char!$A:$A, MATCH(P15, char!$B:$B, 0)), "") | H15: =IFERROR(INDEX(char!$A:$A, MATCH(Q15, char!$B:$B, 0)), "") | I15: =IFERROR(INDEX(char!$A:$A, MATCH(R15, char!$B:$B, 0)), "") | J15: =IFERROR(INDEX(char!$A:$A, MATCH(S15, char!$B:$B, 0)), "") | N15: 陸奥守吉行 | O15: 長曽祢虎徹
A16: 15 | B16: 池田屋事件 市中 | C16: 6-1 | E16: =IFERROR(INDEX(char!$A:$A, MATCH(N16, char!$B:$B, 0)), "") -> 91 | F16: =IFERROR(INDEX(char!$A:$A, MATCH(O16, char!$B:$B, 0)), "") -> 99 | G16: =IFERROR(INDEX(char!$A:$A, MATCH(P16, char!$B:$B, 0)), "") -> 105 | H16: =IFERROR(INDEX(char!$A:$A, MATCH(Q16, char!$B:$B, 0)), "") | I16: =IFERROR(INDEX(char!$A:$A, MATCH(R16, char!$B:$B, 0)), "") | J16: =IFERROR(INDEX(char!$A:$A, MATCH(S16, char!$B:$B, 0)), "") | N16: 和泉守兼定 | O16: 堀川国広 | P16: 長曽祢虎徹
A17: 16 | B17: 池田屋事件 大橋にて | C17: 6-2 | E17: =IFERROR(INDEX(char!$A:$A, MATCH(N17, char!$B:$B, 0)), "") -> 87 | F17: =IFERROR(INDEX(char!$A:$A, MATCH(O17, char!$B:$B, 0)), "") -> 91 | G17: =IFERROR(INDEX(char!$A:$A, MATCH(P17, char!$B:$B, 0)), "") | H17: =IFERROR(INDEX(char!$A:$A, MATCH(Q17, char!$B:$B, 0)), "") | I17: =IFERROR(INDEX(char!$A:$A, MATCH(R17, char!$B:$B, 0)), "") | J17: =IFERROR(INDEX(char!$A:$A, MATCH(S17, char!$B:$B, 0)), "") | N17: 大和守安定 | O17: 和泉守兼定
A18: 17 | B18: 池田屋事件 突入 | C18: 6-3 | E18: =IFERROR(INDEX(char!$A:$A, MATCH(N18, char!$B:$B, 0)), "") -> 85 | F18: =IFERROR(INDEX(char!$A:$A, MATCH(O18, char!$B:$B, 0)), "") -> 87 | G18: =IFERROR(INDEX(char!$A:$A, MATCH(P18, char!$B:$B, 0)), "") | H18: =IFERROR(INDEX(char!$A:$A, MATCH(Q18, char!$B:$B, 0)), "") | I18: =IFERROR(INDEX(char!$A:$A, MATCH(R18, char!$B:$B, 0)), "") | J18: =IFERROR(INDEX(char!$A:$A, MATCH(S18, char!$B:$B, 0)), "") | N18: 加州清光 | O18: 大和守安定
A19: 18 | B19: 池田屋事件 裏庭へ | C19: 6-4 | E19: =IFERROR(INDEX(char!$A:$A, MATCH(N19, char!$B:$B, 0)), "") -> 85 | F19: =IFERROR(INDEX(char!$A:$A, MATCH(O19, char!$B:$B, 0)), "") -> 105 | G19: =IFERROR(INDEX(char!$A:$A, MATCH(P19, char!$B:$B, 0)), "") | H19: =IFERROR(INDEX(char!$A:$A, MATCH(Q19, char!$B:$B, 0)), "") | I19: =IFERROR(INDEX(char!$A:$A, MATCH(R19, char!$B:$B, 0)), "") | J19: =IFERROR(INDEX(char!$A:$A, MATCH(S19, char!$B:$B, 0)), "") | N19: 加州清光 | O19: 長曽祢虎徹
A20: 19 | B20: 博多の話 | C20: 5-2 | E20: =IFERROR(INDEX(char!$A:$A, MATCH(N20, char!$B:$B, 0)), "") -> 43 | F20: =IFERROR(INDEX(char!$A:$A, MATCH(O20, char!$B:$B, 0)), "") -> 136 | G20: =IFERROR(INDEX(char!$A:$A, MATCH(P20, char!$B:$B, 0)), "") | H20: =IFERROR(INDEX(char!$A:$A, MATCH(Q20, char!$B:$B, 0)), "") | I20: =IFERROR(INDEX(char!$A:$A, MATCH(R20, char!$B:$B, 0)), "") | J20: =IFERROR(INDEX(char!$A:$A, MATCH(S20, char!$B:$B, 0)), "") | N20: 博多藤四郎 | O20: 日本号
A21: 20 | B21: 三本の槍 | E21: =IFERROR(INDEX(char!$A:$A, MATCH(N21, char!$B:$B, 0)), "") -> 65 | F21: =IFERROR(INDEX(char!$A:$A, MATCH(O21, char!$B:$B, 0)), "") -> 136 | G21: =IFERROR(INDEX(char!$A:$A, MATCH(P21, char!$B:$B, 0)), "") -> 138 | H21: =IFERROR(INDEX(char!$A:$A, MATCH(Q21, char!$B:$B, 0)), "") | I21: =IFERROR(INDEX(char!$A:$A, MATCH(R21, char!$B:$B, 0)), "") | J21: =IFERROR(INDEX(char!$A:$A, MATCH(S21, char!$B:$B, 0)), "") | N21: 蜻蛉切 | O21: 日本号 | P21: 御手杵
A22: 21 | B22: 黒田家の話 | E22: =IFERROR(INDEX(char!$A:$A, MATCH(N22, char!$B:$B, 0)), "") -> 118 | F22: =IFERROR(INDEX(char!$A:$A, MATCH(O22, char!$B:$B, 0)), "") -> 136 | G22: =IFERROR(INDEX(char!$A:$A, MATCH(P22, char!$B:$B, 0)), "") | H22: =IFERROR(INDEX(char!$A:$A, MATCH(Q22, char!$B:$B, 0)), "") | I22: =IFERROR(INDEX(char!$A:$A, MATCH(R22, char!$B:$B, 0)), "") | J22: =IFERROR(INDEX(char!$A:$A, MATCH(S22, char!$B:$B, 0)), "") | N22: へし切長谷部 | O22: 日本号
A23: 22 | B23: 黒田家の話 その後 | E23: =IFERROR(INDEX(char!$A:$A, MATCH(N23, char!$B:$B, 0)), "") -> 118 | F23: =IFERROR(INDEX(char!$A:$A, MATCH(O23, char!$B:$B, 0)), "") -> 136 | G23: =IFERROR(INDEX(char!$A:$A, MATCH(P23, char!$B:$B, 0)), "") | H23: =IFERROR(INDEX(char!$A:$A, MATCH(Q23, char!$B:$B, 0)), "") | I23: =IFERROR(INDEX(char!$A:$A, MATCH(R23, char!$B:$B, 0)), "") | J23: =IFERROR(INDEX(char!$A:$A, MATCH(S23, char!$B:$B, 0)), "") | N23: へし切長谷部 | O23: 日本号
A24: 23 | B24: 幸運の刀 | C24: 4-2 | E24: =IFERROR(INDEX(char!$A:$A, MATCH(N24, char!$B:$B, 0)), "") -> 35 | F24: =IFERROR(INDEX(char!$A:$A, MATCH(O24, char!$B:$B, 0)), "") -> 67 | G24: =IFERROR(INDEX(char!$A:$A, MATCH(P24, char!$B:$B, 0)), "") | H24: =IFERROR(INDEX(char!$A:$A, MATCH(Q24, char!$B:$B, 0)), "") | I24: =IFERROR(INDEX(char!$A:$A, MATCH(R24, char!$B:$B, 0)), "") | J24: =IFERROR(INDEX(char!$A:$A, MATCH(S24, char!$B:$B, 0)), "") | N24: 後藤藤四郎 | O24: 物吉貞宗
A25: 24 | B25: 源氏の宝剣 | C25: 5-3 | E25: =IFERROR(INDEX(char!$A:$A, MATCH(N25, char!$B:$B, 0)), "") -> 107 | F25: =IFERROR(INDEX(char!$A:$A, MATCH(O25, char!$B:$B, 0)), "") -> 112 | G25: =IFERROR(INDEX(char!$A:$A, MATCH(P25, char!$B:$B, 0)), "") | H25: =IFERROR(INDEX(char!$A:$A, MATCH(Q25, char!$B:$B, 0)), "") | I25: =IFERROR(INDEX(char!$A:$A, MATCH(R25, char!$B:$B, 0)), "") | J25: =IFERROR(INDEX(char!$A:$A, MATCH(S25, char!$B:$B, 0)), "") | N25: 髭切 | O25: 膝丸
A26: 25 | B26: 悲しみと、なぐさめ | C26: 3-2 | E26: =IFERROR(INDEX(char!$A:$A, MATCH(N26, char!$B:$B, 0)), "") -> 118 | F26: =IFERROR(INDEX(char!$A:$A, MATCH(O26, char!$B:$B, 0)), "") -> 120 | G26: =IFERROR(INDEX(char!$A:$A, MATCH(P26, char!$B:$B, 0)), "") | H26: =IFERROR(INDEX(char!$A:$A, MATCH(Q26, char!$B:$B, 0)), "") | I26: =IFERROR(INDEX(char!$A:$A, MATCH(R26, char!$B:$B, 0)), "") | J26: =IFERROR(INDEX(char!$A:$A, MATCH(S26, char!$B:$B, 0)), "") | N26: へし切長谷部 | O26: 不動行光
A27: 26 | B27: 僧と山伏 | E27: =IFERROR(INDEX(char!$A:$A, MATCH(N27, char!$B:$B, 0)), "") -> 97 | F27: =IFERROR(INDEX(char!$A:$A, MATCH(O27, char!$B:$B, 0)), "") -> 17 | G27: =IFERROR(INDEX(char!$A:$A, MATCH(P27, char!$B:$B, 0)), "") | H27: =IFERROR(INDEX(char!$A:$A, MATCH(Q27, char!$B:$B, 0)), "") | I27: =IFERROR(INDEX(char!$A:$A, MATCH(R27, char!$B:$B, 0)), "") | J27: =IFERROR(INDEX(char!$A:$A, MATCH(S27, char!$B:$B, 0)), "") | N27: 山伏国広 | O27: 数珠丸恒次
A28: 27 | B28: 関ヶ原へは…… | C28: 3-1 | E28: =IFERROR(INDEX(char!$A:$A, MATCH(N28, char!$B:$B, 0)), "") -> 69 | F28: =IFERROR(INDEX(char!$A:$A, MATCH(O28, char!$B:$B, 0)), "") -> 116 | G28: =IFERROR(INDEX(char!$A:$A, MATCH(P28, char!$B:$B, 0)), "") | H28: =IFERROR(INDEX(char!$A:$A, MATCH(Q28, char!$B:$B, 0)), "") | I28: =IFERROR(INDEX(char!$A:$A, MATCH(R28, char!$B:$B, 0)), "") | J28: =IFERROR(INDEX(char!$A:$A, MATCH(S28, char!$B:$B, 0)), "") | N28: 太鼓鐘貞宗 | O28: 大倶利伽羅
A29: 28 | B29: 幕府の霊的な守り | C29: 1-2 | E29: =IFERROR(INDEX(char!$A:$A, MATCH(N29, char!$B:$B, 0)), "") -> 13 | F29: =IFERROR(INDEX(char!$A:$A, MATCH(O29, char!$B:$B, 0)), "") -> 15 | G29: =IFERROR(INDEX(char!$A:$A, MATCH(P29, char!$B:$B, 0)), "") | H29: =IFERROR(INDEX(char!$A:$A, MATCH(Q29, char!$B:$B, 0)), "") | I29: =IFERROR(INDEX(char!$A:$A, MATCH(R29, char!$B:$B, 0)), "") | J29: =IFERROR(INDEX(char!$A:$A, MATCH(S29, char!$B:$B, 0)), "") | N29: 大典太光世 | O29: ソハヤノツルキ
A30: 29 | B30: 写しの悲哀 | E30: =IFERROR(INDEX(char!$A:$A, MATCH(N30, char!$B:$B, 0)), "") -> 15 | F30: =IFERROR(INDEX(char!$A:$A, MATCH(O30, char!$B:$B, 0)), "") -> 95 | G30: =IFERROR(INDEX(char!$A:$A, MATCH(P30, char!$B:$B, 0)), "") | H30: =IFERROR(INDEX(char!$A:$A, MATCH(Q30, char!$B:$B, 0)), "") | I30: =IFERROR(INDEX(char!$A:$A, MATCH(R30, char!$B:$B, 0)), "") | J30: =IFERROR(INDEX(char!$A:$A, MATCH(S30, char!$B:$B, 0)), "") | N30: ソハヤノツルキ | O30: 山姥切国広
A31: 30 | B31: 前田家の話 | E31: =IFERROR(INDEX(char!$A:$A, MATCH(N31, char!$B:$B, 0)), "") -> 13 | F31: =IFERROR(INDEX(char!$A:$A, MATCH(O31, char!$B:$B, 0)), "") -> 39 | G31: =IFERROR(INDEX(char!$A:$A, MATCH(P31, char!$B:$B, 0)), "") | H31: =IFERROR(INDEX(char!$A:$A, MATCH(Q31, char!$B:$B, 0)), "") | I31: =IFERROR(INDEX(char!$A:$A, MATCH(R31, char!$B:$B, 0)), "") | J31: =IFERROR(INDEX(char!$A:$A, MATCH(S31, char!$B:$B, 0)), "") | N31: 大典太光世 | O31: 前田藤四郎
A32: 31 | B32: 天下人の霊剣 | E32: =IFERROR(INDEX(char!$A:$A, MATCH(N32, char!$B:$B, 0)), "") -> 15 | F32: =IFERROR(INDEX(char!$A:$A, MATCH(O32, char!$B:$B, 0)), "") -> 67 | G32: =IFERROR(INDEX(char!$A:$A, MATCH(P32, char!$B:$B, 0)), "") | H32: =IFERROR(INDEX(char!$A:$A, MATCH(Q32, char!$B:$B, 0)), "") | I32: =IFERROR(INDEX(char!$A:$A, MATCH(R32, char!$B:$B, 0)), "") | J32: =IFERROR(INDEX(char!$A:$A, MATCH(S32, char!$B:$B, 0)), "") | N32: ソハヤノツルキ | O32: 物吉貞宗
A33: 32 | B33: 九曜と竹雀のえにし 発端 | C33: 7-1 | D33: 対象刀剣男士を一緒に組んでボスマス勝利 | E33: =IFERROR(INDEX(char!$A:$A, MATCH(N33, char!$B:$B, 0)), "") -> 89 | F33: =IFERROR(INDEX(char!$A:$A, MATCH(O33, char!$B:$B, 0)), "") -> 83 | G33: =IFERROR(INDEX(char!$A:$A, MATCH(P33, char!$B:$B, 0)), "") | H33: =IFERROR(INDEX(char!$A:$A, MATCH(Q33, char!$B:$B, 0)), "") | I33: =IFERROR(INDEX(char!$A:$A, MATCH(R33, char!$B:$B, 0)), "") | J33: =IFERROR(INDEX(char!$A:$A, MATCH(S33, char!$B:$B, 0)), "") | N33: 歌仙兼定 | O33: 小夜左文字
A34: 33 | B34: 九曜と竹雀のえにし 勃発 | C34: 7-1 | D34: 回想32発生後 | E34: =IFERROR(INDEX(char!$A:$A, MATCH(N34, char!$B:$B, 0)), "") -> 89 | F34: =IFERROR(INDEX(char!$A:$A, MATCH(O34, char!$B:$B, 0)), "") -> 116 | G34: =IFERROR(INDEX(char!$A:$A, MATCH(P34, char!$B:$B, 0)), "") | H34: =IFERROR(INDEX(char!$A:$A, MATCH(Q34, char!$B:$B, 0)), "") | I34: =IFERROR(INDEX(char!$A:$A, MATCH(R34, char!$B:$B, 0)), "") | J34: =IFERROR(INDEX(char!$A:$A, MATCH(S34, char!$B:$B, 0)), "") | N34: 歌仙兼定 | O34: 大倶利伽羅
A35: 34 | B35: 九曜と竹雀のえにし 接触 | C35: 7-2 | D35: 回想33発生後、対象刀剣男士を一緒に組んでボスマス勝利 | E35: =IFERROR(INDEX(char!$A:$A, MATCH(N35, char!$B:$B, 0)), "") -> 73 | F35: =IFERROR(INDEX(char!$A:$A, MATCH(O35, char!$B:$B, 0)), "") -> 83 | G35: =IFERROR(INDEX(char!$A:$A, MATCH(P35, char!$B:$B, 0)), "") -> 116 | H35: =IFERROR(INDEX(char!$A:$A, MATCH(Q35, char!$B:$B, 0)), "") | I35: =IFERROR(INDEX(char!$A:$A, MATCH(R35, char!$B:$B, 0)), "") | J35: =IFERROR(INDEX(char!$A:$A, MATCH(S35, char!$B:$B, 0)), "") | N35: 燭台切光忠 | O35: 小夜左文字 | P35: 大倶利伽羅
A36: 35 | B36: 九曜と竹雀のえにし 接触・続 | C36: 7-2 | D36: 回想34発生後、対象刀剣男士を一緒に組んでボスマス勝利 | E36: =IFERROR(INDEX(char!$A:$A, MATCH(N36, char!$B:$B, 0)), "") -> 73 | F36: =IFERROR(INDEX(char!$A:$A, MATCH(O36, char!$B:$B, 0)), "") -> 83 | G36: =IFERROR(INDEX(char!$A:$A, MATCH(P36, char!$B:$B, 0)), "") -> 130 | H36: =IFERROR(INDEX(char!$A:$A, MATCH(Q36, char!$B:$B, 0)), "") | I36: =IFERROR(INDEX(char!$A:$A, MATCH(R36, char!$B:$B, 0)), "") | J36: =IFERROR(INDEX(char!$A:$A, MATCH(S36, char!$B:$B, 0)), "") | N36: 燭台切光忠 | O36: 小夜左文字 | P36: 鶴丸国永
A37: 36 | B37: 九曜と竹雀のえにし 協力 | C37: 7-2 | D37: 回想34発生後、対象刀剣男士を一緒に組んでボスマス勝利 | E37: =IFERROR(INDEX(char!$A:$A, MATCH(N37, char!$B:$B, 0)), "") -> 73 | F37: =IFERROR(INDEX(char!$A:$A, MATCH(O37, char!$B:$B, 0)), "") -> 83 | G37: =IFERROR(INDEX(char!$A:$A, MATCH(P37, char!$B:$B, 0)), "") -> 89 | H37: =IFERROR(INDEX(char!$A:$A, MATCH(Q37, char!$B:$B, 0)), "") -> 116 | I37: =IFERROR(INDEX(char!$A:$A, MATCH(R37, char!$B:$B, 0)), "") | J37: =IFERROR(INDEX(char!$A:$A, MATCH(S37, char!$B:$B, 0)), "") | N37: 燭台切光忠 | O37: 小夜左文字 | P37: 歌仙兼定 | Q37: 大倶利伽羅
A38: 37 | B38: 九曜と竹雀のえにし 協力・続 | C38: 7-2 | D38: 回想36発生後、対象刀剣男士を一緒に組んでボスマス勝利 | E38: =IFERROR(INDEX(char!$A:$A, MATCH(N38, char!$B:$B, 0)), "") -> 73 | F38: =IFERROR(INDEX(char!$A:$A, MATCH(O38, char!$B:$B, 0)), "") -> 83 | G38: =IFERROR(INDEX(char!$A:$A, MATCH(P38, char!$B:$B, 0)), "") -> 69 | H38: =IFERROR(INDEX(char!$A:$A, MATCH(Q38, char!$B:$B, 0)), "") -> 89 | I38: =IFERROR(INDEX(char!$A:$A, MATCH(R38, char!$B:$B, 0)), "") -> 116 | J38: =IFERROR(INDEX(char!$A:$A, MATCH(S38, char!$B:$B, 0)), "") | N38: 燭台切光忠 | O38: 小夜左文字 | P38: 太鼓鐘貞宗 | Q38: 歌仙兼定 | R38: 大倶利伽羅
A39: 38 | B39: 九曜と竹雀のえにし 団結 | C39: 7-3 | D39: 回想36発生後、対象刀剣男士を一緒に組んでボスマス勝利 | E39: =IFERROR(INDEX(char!$A:$A, MATCH(N39, char!$B:$B, 0)), "") -> 73 | F39: =IFERROR(INDEX(char!$A:$A, MATCH(O39, char!$B:$B, 0)), "") -> 83 | G39: =IFERROR(INDEX(char!$A:$A, MATCH(P39, char!$B:$B, 0)), "") | H39: =IFERROR(INDEX(char!$A:$A, MATCH(Q39, char!$B:$B, 0)), "") | I39: =IFERROR(INDEX(char!$A:$A, MATCH(R39, char!$B:$B, 0)), "") | J39: =IFERROR(INDEX(char!$A:$A, MATCH(S39, char!$B:$B, 0)), "") | N39: 燭台切光忠 | O39: 小夜左文字
A40: 39 | B40: 九曜と竹雀のえにし 団結・続 | C40: 7-3 | D40: 回想38発生後、対象刀剣男士を一緒に組んでボスマス勝利 | E40: =IFERROR(INDEX(char!$A:$A, MATCH(N40, char!$B:$B, 0)), "") -> 73 | F40: =IFERROR(INDEX(char!$A:$A, MATCH(O40, char!$B:$B, 0)), "") -> 83 | G40: =IFERROR(INDEX(char!$A:$A, MATCH(P40, char!$B:$B, 0)), "") -> 69 | H40: =IFERROR(INDEX(char!$A:$A, MATCH(Q40, char!$B:$B, 0)), "") | I40: =IFERROR(INDEX(char!$A:$A, MATCH(R40, char!$B:$B, 0)), "") | J40: =IFERROR(INDEX(char!$A:$A, MATCH(S40, char!$B:$B, 0)), "") | N40: 燭台切光忠 | O40: 小夜左文字 | P40: 太鼓鐘貞宗
...

Sheet area
A1: area | B1: name | C1: normalExp | D1: bossExp | E1: mokutan | F1: tamahagane | G1: reikyakuzai | H1: toishi | I1: iraihuda | J1: time | K1: field | L1: weather
A2: 1-1 | B2: 函館 | C2: 30 | D2: 90 | J2: 昼 | K2: 野戦 | L2: 晴
A3: 1-2 | B3: 会津 | C3: 50 | D3: 150 | E3: 10 | J3: 昼 | K3: 野戦 | L3: 晴
A4: 1-3 | B4: 宇都宮 | C4: 80 | D4: 240 | H4: 10 | J4: 昼 | K4: 野戦 | L4: 晴
A5: 1-4 | B5: 鳥羽 | C5: 100 | D5: 300 | E5: 15 | G5: 10 | J5: 昼 | K5: 野戦 | L5: 晴
A6: 2-1 | B6: 鳥羽 | C6: 120 | D6: 360 | F6: 15 | H6: 15 | J6: 昼 | K6: 野戦 | L6: 晴
A7: 2-2 | B7: 江戸 | C7: 140 | D7: 420 | E7: 30 | J7: 昼 | K7: 野戦 | L7: 晴
A8: 2-3 | B8: 江戸（元禄） | C8: 170 | D8: 510 | G8: 30 | J8: 昼 | K8: 野戦 | L8: 晴
A9: 2-4 | B9: 大阪（大阪冬の陣） | C9: 200 | D9: 600 | I9: 〇 | J9: 昼 | K9: 野戦 | L9: 晴
A10: 3-1 | B10: 関ヶ原 | C10: 230 | D10: 690 | H10: 20 | J10: 昼 | K10: 野戦 | L10: 晴
A11: 3-2 | B11: 本能寺 | C11: 250 | D11: 750 | F11: 30 | I11: 〇 | J11: 昼 | K11: 野戦 | L11: 晴
A12: 3-3 | B12: 越前 | C12: 280 | D12: 840 | E12: 50 | F12: 50 | J12: 昼 | K12: 野戦 | L12: 晴
A13: 3-4 | B13: 安土 | C13: 320 | D13: 960 | H13: 40 | I13: 〇 | J13: 昼 | K13: 野戦 | L13: 晴
A14: 4-1 | B14: 長篠 | C14: 360 | D14: 1080 | G14: 40 | I14: 〇 | J14: 昼 | K14: 野戦 | L14: 晴
A15: 4-2 | B15: 三方ヶ原 | C15: 390 | D15: 1170 | H15: 60 | J15: 昼 | K15: 野戦 | L15: 晴
A16: 4-3 | B16: 桶狭間 | C16: 400 | D16: 1200 | E16: 65 | F16: 65 | G16: 65 | J16: 昼 | K16: 野戦 | L16: 晴
A17: 4-4 | B17: 京都（西陣） | C17: 420 | D17: 1260 | G17: 65 | I17: 〇 | J17: 昼 | K17: 野戦 | L17: 晴
A18: 5-1 | B18: 鎌倉（元弘の乱） | C18: 440 | D18: 1320 | E18: 60 | J18: 昼 | K18: 野戦 | L18: 晴
A19: 5-2 | B19: 博多湾（元寇） | C19: 460 | D19: 1380 | E19: 70 | F19: 60 | G19: 85 | J19: 昼 | K19: 野戦 | L19: 晴
A20: 5-3 | B20: 墨俣（承久の乱） | C20: 480 | D20: 1440 | F20: 90 | H20: 90 | J20: 昼 | K20: 野戦 | L20: 晴
A21: 5-4 | B21: 厚樫山（阿津賀志山の戦い） | C21: 500 | D21: 1500 | E21: 80 | G21: 90 | J21: 昼 | K21: 野戦 | L21: 晴
A22: 6-1 | B22: 京都（市中） | C22: 510 | D22: 1600 | G22: 80 | H22: 70 | J22: 夜 | K22: 市街 | L22: 晴
A23: 6-2 | B23: 京都（三条大橋） | C23: 520,250,550,580 | D23: 1620 | F23: 80 | G23: 70 | J23: 夜 | K23: 市街 | L23: 晴
A24: 6-3 | B24: 京都（池田屋二階） | C24: 530,270,560,590,620 | D24: 1640 | E24: 40 | F24: 10 | I24: 〇 | J24: 夜 | K24: 屋内 | L24: 晴
A25: 6-4 | B25: 京都（池田屋一階） | C25: 220,190 | D25: 1880 | E25: 80 | H25: 70 | J25: 夜(ボス昼) | K25: 屋内(ボス市街) | L25: 晴
A26: 7-1 | B26: 江戸（新橋） | C26: 300,400,1000 | D26: 3000 | E26: 140 | F26: 100 | G26: 100 | I26: 〇 | J26: 昼 | K26: 市街 | L26: 晴
A27: 7-2 | B27: 江戸（白金台） | C27: 200,300,400,550,1000 | D27: 3000 | E27: 100 | F27: 100 | G27: 100 | H27: 100 | I27: 〇 | J27: 昼 | K27: 市街 | L27: 雨
A28: 7-3 | B28: 江戸（江戸城下） | C28: 500,600,1000,1500 | D28: 3000 | E28: 70 | F28: 70 | G28: 70 | H28: 70 | J28: 昼 | K28: 市街 | L28: 晴
A29: 7-4 | B29: 江戸（江戸城内） | C29: 400/800/1200 | D29: 2000/4000/6000 | J29: 夜 | K29: 屋内 | L29: 晴
A30: 8-1 | B30: 京都（阿弥陀ヶ峰） | C30: 750,800 | D30: 3500 | E30: 120 | F30: 120 | G30: 120 | H30: 120 | I30: 〇 | J30: 昼 | K30: 野戦 | L30: 晴
A31: 8-2 | B31: 信濃（上田城） | C31: 800,850,1000 | D31: 4000 | E31: 125 | F31: 125 | G31: 125 | H31: 125 | I31: 〇 | J31: 昼 | K31: 野戦 | L31: 晴
A32: 8-3 | B32: 美濃（青野原） | C32: 850,900 | D32: 4500 | E32: 130 | F32: 130 | G32: 130 | H32: 130 | I32: 〇 | J32: 昼 | K32: 野戦 | L32: 霧雨
A33: 8-4 | B33: 京都（五条） | C33: 900,950 | D33: 5000 | E33: 135 | F33: 135 | G33: 135 | H33: 135 | I33: 〇 | J33: 昼 | K33: 市街/野戦(ボス) | L33: 晴

Sheet drop
A1: area | B1: node_type | C1: id
A2: 1-1 | B2: N | C2: =IFERROR(INDEX(char!$A:$A, MATCH(E2, char!$B:$B, 0)), "未登録") -> 39 | E2: 前田藤四郎
A3: 1-1 | B3: N | C3: =IFERROR(INDEX(char!$A:$A, MATCH(E3, char!$B:$B, 0)), "未登録") -> 41 | E3: 秋田藤四郎
A4: 1-1 | B4: N | C4: =IFERROR(INDEX(char!$A:$A, MATCH(E4, char!$B:$B, 0)), "未登録") -> 45 | E4: 乱藤四郎
A5: 1-1 | B5: N | C5: =IFERROR(INDEX(char!$A:$A, MATCH(E5, char!$B:$B, 0)), "未登録") -> 47 | E5: 五虎退
A6: 1-1 | B6: N | C6: =IFERROR(INDEX(char!$A:$A, MATCH(E6, char!$B:$B, 0)), "未登録") -> 49 | E6: 薬研藤四郎
A7: 1-1 | B7: N | C7: =IFERROR(INDEX(char!$A:$A, MATCH(E7, char!$B:$B, 0)), "未登録") -> 61 | E7: 愛染国俊
A8: 1-1 | B8: N | C8: =IFERROR(INDEX(char!$A:$A, MATCH(E8, char!$B:$B, 0)), "未登録") -> 83 | E8: 小夜左文字
A9: 1-1 | B9: B | C9: =IFERROR(INDEX(char!$A:$A, MATCH(E9, char!$B:$B, 0)), "未登録") -> 39 | E9: 前田藤四郎
A10: 1-1 | B10: B | C10: =IFERROR(INDEX(char!$A:$A, MATCH(E10, char!$B:$B, 0)), "未登録") -> 41 | E10: 秋田藤四郎
A11: 1-1 | B11: B | C11: =IFERROR(INDEX(char!$A:$A, MATCH(E11, char!$B:$B, 0)), "未登録") -> 45 | E11: 乱藤四郎
A12: 1-1 | B12: B | C12: =IFERROR(INDEX(char!$A:$A, MATCH(E12, char!$B:$B, 0)), "未登録") -> 47 | E12: 五虎退
A13: 1-1 | B13: B | C13: =IFERROR(INDEX(char!$A:$A, MATCH(E13, char!$B:$B, 0)), "未登録") -> 49 | E13: 薬研藤四郎
... A1663: 8-4 | B1663: B | C1663: =IFERROR(INDEX(char!$A:$A, MATCH(E1663, char!$B:$B, 0)), "未登録") -> 152 | E1663: 静形薙刀
A1664: 検非違使 | C1664: =IFERROR(INDEX(char!$A:$A, MATCH(E1664, char!$B:$B, 0)), "未登録") -> 11 | E1664: 今剣
A1665: 検非違使 | C1665: =IFERROR(INDEX(char!$A:$A, MATCH(E1665, char!$B:$B, 0)), "未登録") -> 33 | E1665: 厚藤四郎
A1666: 検非違使 | C1666: =IFERROR(INDEX(char!$A:$A, MATCH(E1666, char!$B:$B, 0)), "未登録") -> 35 | E1666: 後藤藤四郎
A1667: 検非違使 | C1667: =IFERROR(INDEX(char!$A:$A, MATCH(E1667, char!$B:$B, 0)), "未登録") -> 37 | E1667: 信濃藤四郎
A1668: 検非違使 | C1668: =IFERROR(INDEX(char!$A:$A, MATCH(E1668, char!$B:$B, 0)), "未登録") -> 142 | E1668: 毛利藤四郎
A1669: 検非違使 | C1669: =IFERROR(INDEX(char!$A:$A, MATCH(E1669, char!$B:$B, 0)), "未登録") -> 19 | E1669: にっかり青江
A1670: 検非違使 | C1670: =IFERROR(INDEX(char!$A:$A, MATCH(E1670, char!$B:$B, 0)), "未登録") -> 27 | E1670: 鯰尾藤四郎
A1671: 検非違使 | C1671: =IFERROR(INDEX(char!$A:$A, MATCH(E1671, char!$B:$B, 0)), "未登録") -> 29 | E1671: 骨喰藤四郎
A1672: 検非違使 | C1672: =IFERROR(INDEX(char!$A:$A, MATCH(E1672, char!$B:$B, 0)), "未登録") -> 99 | E1672: 堀川国広
A1673: 検非違使 | C1673: =IFERROR(INDEX(char!$A:$A, MATCH(E1673, char!$B:$B, 0)), "未登録") -> 196 | E1673: 泛塵
A1674: 検非違使 | C1674: =IFERROR(INDEX(char!$A:$A, MATCH(E1674, char!$B:$B, 0)), "未登録") -> 23 | E1674: 鳴狐
A1675: 検非違使 | C1675: =IFERROR(INDEX(char!$A:$A, MATCH(E1675, char!$B:$B, 0)), "未登録") -> 63 | E1675: 千子村正
... A1796: 鍛刀 | C1796: =IFERROR(INDEX(char!$A:$A, MATCH(E1796, char!$B:$B, 0)), "未登録") -> 152 | E1796: 静形薙刀
